Workbook
Name Conversion_Rate: Assumptions!$G$8

Sheet Cover
B14: Date: | F14: =NOW()
B15: Contact: | F15: nick@careerxl.com
B16: Website: | F16: careerxl.com
B19: PRIVATE - NOT FOR REDISTRIBUTION

Sheet Inputs ->

Sheet Assumptions
C3: Assumptions | K3: Formatting
C5: Company Name: | G5: Copart, Inc. (CPRT) | O5: R | P5: G | Q5: B
C6: Historicals Start Date | G6: =YEAR(G7)-3 | K6: Header | O6: 22 | P6: 57 | Q6: 91
C7: LTM Period | G7: 46234 | K7: Emphasis 1 | O7: 221 | P7: 221 | Q7: 221
C8: Conversion Rate | G8: 1 | K8: Emphasis 2 | O8: 191 | P8: 191 | Q8: 191
C9: Units | G9: ($ in millions) | K9: Emphasis 3 | O9: 255 | P9: 242 | Q9: 204
K11: Hardcoded | O11: 0 | P11: 0 | Q11: 252
K12: Formulas | O12: 0 | P12: 0 | Q12: 0
K13: Linked Outside of Sheet | O13: 0 | P13: 128 | Q13: 0
K14: Linked Inside of Sheet | O14: 128 | P14: 0 | Q14: 128
K15: Unique Entry / Formula | O15: 255 | P15: 0 | Q15: 0

Sheet Model Notes
C3: Model Notes - Copart, Inc. (CPRT) SHORT
C5: 1 | D5: Short CPRT at $27.36 (Sep 30, 2026), target $21.50 (-21%), 6-12 months. Copart is a toll road paid per car, and fewer cars are using the road. Target = 15x FY27E EPS of $1.44; DCF, comps and LBO are cross-checks. Printed case = memo base case (Support!D16 = 2); bear $16.84 / bull $33.90 sit on the switch; probability-weighted $23.45 is a note.
C6: =+C5+1 | D6: Three mechanisms, each a driver. (a) Structural claim decline: units -3% FY27E (Drivers row 192); insurance CPI +49% and repair CPI +57% since 2019, miles driven already 2% above 2019, AEB mandatory Sep 2029. (b) Share loss to IAA: 63.9% to 61.4%, ~167k cars, ~$166M service revenue, Progressive ~90% to IAA (Support rows 62-80). (c) Operating leverage the wrong way: Q4 facility cost per car +14.2% vs revenue per car +5.4%; margin to 33.0% (row 204); interest income $182M to $110M (row 207).
C7: =+C6+1 | D7: Margin path (what drops). Operating margin (Drivers row 204): 38.4% FY23A, 37.1%, 36.5%, 35.4% FY26A, 33.0% FY27E. FY23A-FY26A, -300bp of revenue: G&A +263bp, facility operations +206bp, D&A +98bp, less cost of vehicle sales -267bp. FY26A-FY27E, -242bp: facility operations +227bp, D&A +15bp; G&A and cost of vehicle sales held at FY26 rates. Cause: a growing cost base serves fewer cars. Q4 FY26 US facility cost rose 7.7% on 5.7% fewer US cars (+14.2% per car); management cites long-haul delivery ($17M of the increase), Title Express, wholesale yards and new capacity. Base FY27E: facility cost +$122M (+7.0%) on 3% fewer cars; cost per car +10.3% vs revenue per car +4.0%.
C8: =+C7+1 | D8: Margin path (why 33.0%, and why it holds). FY27E is not a new leg down: FY26A's 35.4% blends 36.5% for the first nine months with a 32.0% Q4 exit ($368.9M / $1,152.4M), so 33.0% sits 100bp above the exit rate. Held to FY36E (Drivers row 205 = 0): units grow only +0.5% a year from FY30E, so no volume re-absorbs yard cost. Management says it will cut cost per car but gives no guidance; no credit given. +100bp of FY27E margin = ~$47M EBIT, ~$0.04 EPS, ~$0.61 on the target; bull case 36.5% = FY25A level. Net margin falls more (31.8% to 28.5%) as interest income drops from $182M to $110M after the ACV payment.
C9: =+C8+1 | D9: Variant view: Street has FY27 EPS $1.75 (+11% per memo) and treats 17.6x vs a 34x ten-year median as a cyclical dip. Model FY27E EPS $1.44, 18% below; Street is a reference cell only (Support!D10). Unlike prior 30%+ drawdowns, trailing EPS is falling.
C10: =+C9+1 | D10: Falsifiers: cover if collision frequency is positive for two quarters; the lost-customer lap is already in the -3% unit assumption; catastrophe volume is excluded from the trend; stop reference $32.60 (above the 50-day and the 23.6% retracement). Short interest 4.6% of float is context, not an input.
C11: =+C10+1 | D11: Catalysts: Q1 FY27 on Nov 19, 2026 (Street $0.40 vs $0.41); RB Global Q3 in early Nov; ACV close by year-end 2026; monthly CCC / insurer claim prints.
C12: =+C11+1 | D12: Column map (no columns inserted): G = FY2023A (year ended July 31, 2023), H = FY2024A, I = FY2025A, J = FY2026A / LTM (July 31, 2026), K-T = FY2027E-FY2036E. Pitch window FY27E-FY31E; FY32E-FY36E fade (units +0.5%, revenue per unit to +1.5%, margin flat). DCF columns G-P = FY27E-FY36E. Units: $ millions except per share; shares in millions.
C13: =+C12+1 | D13: Definitions. Cash = cash, equivalents, restricted cash + held-to-maturity securities ($4,489.8M FY26). Debt = revolver + term loan = 0; finance leases are not split out on the balance sheet (immaterial) and sit in lease liabilities. Capex and buybacks are negative (template sign). Net income = attributable to Copart: NCI loss runs through Other (Income)/Expense, so template EBT = reported pre-tax income + NCI loss ($3.9M FY26). Facility operations and G&A include their SBC; D&A is the cash-flow-statement total, so template gross profit is before D&A (reported FY26 gross profit $2,083.9M = template $2,294.6M - $201.7M facility D&A - $9.1M).
C14: =+C13+1 | D14: Filing vs memo flags. ACV: 8-K says ~$1.9B equity value; memo ~$1.8B; model uses $1.9B. Revenue $4,666M (memo $4.67B), operating income $1,652.6M, EPS $1.55, buybacks $1,632.5M, interest income net $181.9M: all tie. EV/EBITDA on CFS D&A is 11.0x vs memo 11.1x. Street growth is +12.8% on $1.55, memo says +11%. Memo Exhibit 2 base target is $21.54 vs headline $21.50. Bull EPS computes to $1.67 vs memo $1.70 (see Support row 35). Unit levels are an index on the memo 4.0M base; Copart discloses growth rates only.
C15: =+C14+1 | D15: Template formula changes (logged, none to force a result): first forecast column rolls from J (FY26A) instead of I; EPS row on Multiples & Ratios was market cap / shares, now net income / shares; Summary FCF rows for interest, other and taxes now subtract; Financial Model H127:I127, Drivers G148:J148 (pointed at retained earnings) and L150:T150 reference fixes; LBO management rollover made non-circular; historical reconciling line (row 131) closes the derived cash-flow statement in FY23-FY26 only; DCF cost of debt and capital structure are inputs per brief; LBO cash is after ACV and row 83 excludes acquisitions; Comps stats wrapped in IFERROR.
C16: =+C15+1 | D16: Open items left blank and flagged, not invented: OPENLANE multiples and RBA / LKQ full comps lines as of Sep 30, 2026 (only memo forward P/Es loaded); ACV EV and profit measure (not in the 8-K); gross PP&E / accumulated depreciation split; FY23 unit KPIs; IAA unit forecast (KPI 3 forecast = n/a); 2-year weekly beta not re-estimated (1.0 per brief); 10-K cover share count. DCF vs target and LBO IRR: see Support rows 88-116.

Sheet Dashboard ->

Sheet Summary
C3: =Assumptions!G5
C4: Financial Summary | J4: FY26A / LTM
C5: =+Assumptions!G9 | G5: ='Historical Financials'!G5 | H5: ='Historical Financials'!H5 | I5: ='Historical Financials'!I5 | J5: ='Historical Financials'!J5 | K5: ='Financial Model'!K5 | L5: ='Financial Model'!L5 | M5: ='Financial Model'!M5 | N5: ='Financial Model'!N5 | O5: ='Financial Model'!O5 | P5: ='Financial Model'!P5 | Q5: ='Financial Model'!Q5 | R5: ='Financial Model'!R5 | ... T5: ='Financial Model'!T5
C7: ='Financial Model'!C9 | G7: ='Financial Model'!G9 | H7: ='Financial Model'!H9 | I7: ='Financial Model'!I9 | J7: ='Financial Model'!J9 | K7: ='Financial Model'!K9 | L7: ='Financial Model'!L9 | M7: ='Financial Model'!M9 | N7: ='Financial Model'!N9 | ... T7: ='Financial Model'!T9
C8: % Growth | G8: ='Financial Model'!$G$10 | H8: =+H7/G7-1 | I8: =+I7/H7-1 | J8: ='Financial Model'!$J$10 | K8: =+K7/J7-1 | L8: =+L7/K7-1 | M8: =+M7/L7-1 | N8: =+N7/M7-1 | O8: =+O7/N7-1 | P8: =+P7/O7-1 | Q8: =+Q7/P7-1 | R8: =+R7/Q7-1 | ... T8: =+T7/S7-1
C10: ='Financial Model'!C18 | G10: ='Financial Model'!G18 | H10: ='Financial Model'!H18 | I10: ='Financial Model'!I18 | J10: ='Financial Model'!J18 | K10: ='Financial Model'!K18 | L10: ='Financial Model'!L18 | M10: ='Financial Model'!M18 | N10: ='Financial Model'!N18 | ... T10: ='Financial Model'!T18
C11: % Gross Margin | G11: =+G10/G$7 | H11: =+H10/H$7 | I11: =+I10/I$7 | J11: =+J10/J$7 | K11: =+K10/K$7 | L11: =+L10/L$7 | M11: =+M10/M$7 | N11: =+N10/N$7 | ... T11: =+T10/T$7
C13: ='Financial Model'!C24 | G13: ='Financial Model'!G24 | H13: ='Financial Model'!H24 | I13: ='Financial Model'!I24 | J13: ='Financial Model'!J24 | K13: ='Financial Model'!K24 | L13: ='Financial Model'!L24 | M13: ='Financial Model'!M24 | N13: ='Financial Model'!N24 | ... T13: ='Financial Model'!T24
C14: ='Financial Model'!C25 | G14: =+G13/G$7 | H14: =+H13/H$7 | I14: =+I13/I$7 | J14: =+J13/J$7 | K14: =+K13/K$7 | L14: =+L13/L$7 | M14: =+M13/M$7 | N14: =+N13/N$7 | ... T14: =+T13/T$7
C16: ='Financial Model'!C27 | G16: ='Financial Model'!G27 | H16: ='Financial Model'!H27 | I16: ='Financial Model'!I27 | J16: ='Financial Model'!J27 | K16: ='Financial Model'!K27 | L16: ='Financial Model'!L27 | M16: ='Financial Model'!M27 | N16: ='Financial Model'!N27 | ... T16: ='Financial Model'!T27
C17: ='Financial Model'!C28 | G17: =+G16/G$7 | H17: =+H16/H$7 | I17: =+I16/I$7 | J17: =+J16/J$7 | K17: =+K16/K$7 | L17: =+L16/L$7 | M17: =+M16/M$7 | N17: =+N16/N$7 | ... T17: =+T16/T$7
C19: - Interest | G19: =-'Financial Model'!G34 | H19: =-'Financial Model'!H34 | I19: =-'Financial Model'!I34 | J19: =-'Financial Model'!J34 | K19: =-'Financial Model'!K34 | L19: =-'Financial Model'!L34 | M19: =-'Financial Model'!M34 | N19: =-'Financial Model'!N34 | ... T19: =-'Financial Model'!T34
C20: - Other Expenses | G20: =-'Financial Model'!G35 | H20: =-'Financial Model'!H35 | I20: =-'Financial Model'!I35 | J20: =-'Financial Model'!J35 | K20: =-'Financial Model'!K35 | L20: =-'Financial Model'!L35 | M20: =-'Financial Model'!M35 | N20: =-'Financial Model'!N35 | ... T20: =-'Financial Model'!T35
C21: - Taxes | G21: =-'Financial Model'!G38 | H21: =-'Financial Model'!H38 | I21: =-'Financial Model'!I38 | J21: =-'Financial Model'!J38 | K21: =-'Financial Model'!K38 | L21: =-'Financial Model'!L38 | M21: =-'Financial Model'!M38 | N21: =-'Financial Model'!N38 | ... T21: =-'Financial Model'!T38
C22: +/- ∆ Net Working Capital | G22: ='Financial Model'!G114 | H22: ='Financial Model'!H114 | I22: ='Financial Model'!I114 | J22: ='Financial Model'!J114 | K22: ='Financial Model'!K114 | L22: ='Financial Model'!L114 | M22: ='Financial Model'!M114 | N22: ='Financial Model'!N114 | ... T22: ='Financial Model'!T114
C23: - Capex | G23: ='Financial Model'!G118 | H23: ='Financial Model'!H118 | I23: ='Financial Model'!I118 | J23: ='Financial Model'!J118 | K23: ='Financial Model'!K118 | L23: ='Financial Model'!L118 | M23: ='Financial Model'!M118 | N23: ='Financial Model'!N118 | ... T23: ='Financial Model'!T118
C24: Free Cash Flow (FCF) | G24: =SUM(G19:G23)+G16 | H24: =SUM(H19:H23)+H16 | I24: =SUM(I19:I23)+I16 | J24: =SUM(J19:J23)+J16 | K24: =SUM(K19:K23)+K16 | L24: =SUM(L19:L23)+L16 | M24: =SUM(M19:M23)+M16 | N24: =SUM(N19:N23)+N16 | ... T24: =SUM(T19:T23)+T16
C25: % FCF Margin | G25: =+G24/G$7 | H25: =+H24/H$7 | I25: =+I24/I$7 | J25: =+J24/J$7 | K25: =+K24/K$7 | L25: =+L24/L$7 | M25: =+M24/M$7 | N25: =+N24/N$7 | ... T25: =+T24/T$7
C26: % FCF Growth | G26: n/a | H26: =+H24/G24-1 | I26: =+I24/H24-1 | J26: =+J24/I24-1 | K26: =+K24/J24-1 | L26: =+L24/K24-1 | M26: =+M24/L24-1 | N26: =+N24/M24-1 | O26: =+O24/N24-1 | ... T26: =+T24/S24-1
C28: Key Performance Indicators
C29: ='Multiples & Ratios'!C20 | G29: ='Multiples & Ratios'!G20 | H29: ='Multiples & Ratios'!H20 | I29: ='Multiples & Ratios'!I20 | J29: ='Multiples & Ratios'!J20 | K29: ='Multiples & Ratios'!K20 | L29: ='Multiples & Ratios'!L20 | M29: ='Multiples & Ratios'!M20 | N29: ='Multiples & Ratios'!N20 | ... T29: ='Multiples & Ratios'!T20
C30: ='Multiples & Ratios'!C21 | G30: ='Multiples & Ratios'!G21 | H30: ='Multiples & Ratios'!H21 | I30: ='Multiples & Ratios'!I21 | J30: ='Multiples & Ratios'!J21 | K30: ='Multiples & Ratios'!K21 | L30: ='Multiples & Ratios'!L21 | M30: ='Multiples & Ratios'!M21 | N30: ='Multiples & Ratios'!N21 | ... T30: ='Multiples & Ratios'!T21
C31: ='Multiples & Ratios'!C22 | G31: ='Multiples & Ratios'!G22 | H31: ='Multiples & Ratios'!H22 | I31: ='Multiples & Ratios'!I22 | J31: ='Multiples & Ratios'!J22 | K31: ='Multiples & Ratios'!K22 | L31: ='Multiples & Ratios'!L22 | M31: ='Multiples & Ratios'!M22 | N31: ='Multiples & Ratios'!N22 | ... T31: ='Multiples & Ratios'!T22
C33: Efficiency Ratios
C34: ='Multiples & Ratios'!C25 | G34: ='Multiples & Ratios'!G25 | H34: ='Multiples & Ratios'!H25 | I34: ='Multiples & Ratios'!I25 | J34: ='Multiples & Ratios'!J25 | K34: ='Multiples & Ratios'!K25 | L34: ='Multiples & Ratios'!L25 | M34: ='Multiples & Ratios'!M25 | N34: ='Multiples & Ratios'!N25 | ... T34: ='Multiples & Ratios'!T25
C35: ='Multiples & Ratios'!C26 | G35: ='Multiples & Ratios'!G26 | H35: ='Multiples & Ratios'!H26 | I35: ='Multiples & Ratios'!I26 | J35: ='Multiples & Ratios'!J26 | K35: ='Multiples & Ratios'!K26 | L35: ='Multiples & Ratios'!L26 | M35: ='Multiples & Ratios'!M26 | N35: ='Multiples & Ratios'!N26 | ... T35: ='Multiples & Ratios'!T26
C36: ='Multiples & Ratios'!C27 | G36: ='Multiples & Ratios'!G27 | H36: ='Multiples & Ratios'!H27 | I36: ='Multiples & Ratios'!I27 | J36: ='Multiples & Ratios'!J27 | K36: ='Multiples & Ratios'!K27 | L36: ='Multiples & Ratios'!L27 | M36: ='Multiples & Ratios'!M27 | N36: ='Multiples & Ratios'!N27 | ... T36: ='Multiples & Ratios'!T27
C37: ='Multiples & Ratios'!C28 | G37: ='Multiples & Ratios'!G28 | H37: ='Multiples & Ratios'!H28 | I37: ='Multiples & Ratios'!I28 | J37: ='Multiples & Ratios'!J28 | K37: ='Multiples & Ratios'!K28 | L37: ='Multiples & Ratios'!L28 | M37: ='Multiples & Ratios'!M28 | N37: ='Multiples & Ratios'!N28 | ... T37: ='Multiples & Ratios'!T28
C39: Valuation Multiples
C40: ='Multiples & Ratios'!C8 | G40: ='Multiples & Ratios'!G8 | H40: ='Multiples & Ratios'!H8 | I40: ='Multiples & Ratios'!I8 | J40: ='Multiples & Ratios'!J8 | K40: ='Multiples & Ratios'!K8 | L40: ='Multiples & Ratios'!L8 | M40: ='Multiples & Ratios'!M8 | N40: ='Multiples & Ratios'!N8 | ... T40: ='Multiples & Ratios'!T8
C41: ='Multiples & Ratios'!C9 | G41: ='Multiples & Ratios'!G9 | H41: ='Multiples & Ratios'!H9 | I41: ='Multiples & Ratios'!I9 | J41: ='Multiples & Ratios'!J9 | K41: ='Multiples & Ratios'!K9 | L41: ='Multiples & Ratios'!L9 | M41: ='Multiples & Ratios'!M9 | N41: ='Multiples & Ratios'!N9 | ... T41: ='Multiples & Ratios'!T9
C42: ='Multiples & Ratios'!C10 | G42: ='Multiples & Ratios'!G10 | H42: ='Multiples & Ratios'!H10 | I42: ='Multiples & Ratios'!I10 | J42: ='Multiples & Ratios'!J10 | K42: ='Multiples & Ratios'!K10 | L42: ='Multiples & Ratios'!L10 | M42: ='Multiples & Ratios'!M10 | N42: ='Multiples & Ratios'!N10 | ... T42: ='Multiples & Ratios'!T10
C43: ='Multiples & Ratios'!C11 | G43: ='Multiples & Ratios'!G11 | H43: ='Multiples & Ratios'!H11 | I43: ='Multiples & Ratios'!I11 | J43: ='Multiples & Ratios'!J11 | K43: ='Multiples & Ratios'!K11 | L43: ='Multiples & Ratios'!L11 | M43: ='Multiples & Ratios'!M11 | N43: ='Multiples & Ratios'!N11 | ... T43: ='Multiples & Ratios'!T11

Sheet Summary Charts
O33: =Summary!G5 | P33: =Summary!H5 | Q33: =Summary!I5 | R33: =Summary!J5 | S33: =Summary!K5 | T33: =Summary!L5 | U33: =Summary!M5
L35: Revenue Growth | O35: =Summary!G8 | P35: =Summary!H8 | Q35: =Summary!I8 | R35: =Summary!J8 | S35: =Summary!K8 | T35: =Summary!L8 | U35: =Summary!M8
L36: Gross Margin | O36: =Summary!G11 | P36: =Summary!H11 | Q36: =Summary!I11 | R36: =Summary!J11 | S36: =Summary!K11 | T36: =Summary!L11 | U36: =Summary!M11
L37: Opex (% of Revenue) | O37: =Summary!G14 | P37: =Summary!H14 | Q37: =Summary!I14 | R37: =Summary!J14 | S37: =Summary!K14 | T37: =Summary!L14 | U37: =Summary!M14
L38: FCF Margin | O38: =Summary!G25 | P38: =Summary!H25 | Q38: =Summary!I25 | R38: =Summary!J25 | S38: =Summary!K25 | T38: =Summary!L25 | U38: =Summary!M25
L39: FCF Growth | O39: =Summary!G26 | P39: =Summary!H26 | Q39: =Summary!I26 | R39: =Summary!J26 | S39: =Summary!K26 | T39: =Summary!L26 | U39: =Summary!M26
L41: =Summary!C29 | O41: =Summary!G29 | P41: =Summary!H29 | Q41: =Summary!I29 | R41: =Summary!J29 | S41: =Summary!K29 | T41: =Summary!L29 | U41: =Summary!M29
L42: =Summary!C30 | O42: =Summary!G30 | P42: =Summary!H30 | Q42: =Summary!I30 | R42: =Summary!J30 | S42: =Summary!K30 | T42: =Summary!L30 | U42: =Summary!M30
L43: =Summary!C31 | O43: =Summary!G31 | P43: =Summary!H31 | Q43: =Summary!I31 | R43: =Summary!J31 | S43: =Summary!K31 | T43: =Summary!L31 | U43: =Summary!M31
L45: ROE | O45: =Summary!G34 | P45: =Summary!H34 | Q45: =Summary!I34 | R45: =Summary!J34 | S45: =Summary!K34 | T45: =Summary!L34 | U45: =Summary!M34
L46: ROA | O46: =Summary!G35 | P46: =Summary!H35 | Q46: =Summary!I35 | R46: =Summary!J35 | S46: =Summary!K35 | T46: =Summary!L35 | U46: =Summary!M35
L47: ROIC | O47: =Summary!G36 | P47: =Summary!H36 | Q47: =Summary!I36 | R47: =Summary!J36 | S47: =Summary!K36 | T47: =Summary!L36 | U47: =Summary!M36
L48: EPS | O48: =Summary!G37 | P48: =Summary!H37 | Q48: =Summary!I37 | R48: =Summary!J37 | S48: =Summary!K37 | T48: =Summary!L37 | U48: =Summary!M37

Sheet Financials ->

Sheet Historical Financials
G1: =Assumptions!$G$6 | H1: =+G1+1 | I1: =+H1+1 | J1: =Assumptions!G7 | M1: X
M2: X
C3: =Assumptions!G5&" - Financial Inputs Tab" | M3: X
J4: FY26A / LTM
G5: ="FY"&G1&"A" | H5: ="FY"&H1&"A" | I5: ="FY"&I1&"A" | J5: ="FY"&YEAR(J1)&"A" | M5: X
M6: X
C7: Income Statement | M7: X
M8: X
C9: Service revenues | G9: 3198.128 | H9: 3561.002 | I9: 3968.662 | J9: 3969.52 | M9: X
C10: Vehicle sales | G10: 671.39 | H10: 675.821 | I10: 678.296 | J10: 696.689 | M10: X
C11: Total Revenue | G11: =SUM(G9:G10) | H11: =SUM(H9:H10) | I11: =SUM(I9:I10) | J11: =SUM(J9:J10) | M11: X
M12: X
C13: Facility operations (incl. facility SBC; ex-D&A) | G13: =1369.006+6.926-(159.684-142.097-17.381) | H13: =1532.484+6.95-(190.256-170.65-19.111) | I13: =1744.436+8.107-(217.784-191.775-24.074) | J13: =1755.747+8.472-(238.466-201.669-27.704) | M13: X
C14: Cost of vehicle sales | G14: 614.498 | H14: 619.487 | I14: 602.997 | J14: 616.463 | M14: X
C15: Total COGS | G15: =SUM(G13:G14) | H15: =SUM(H13:H14) | I15: =SUM(I13:I14) | J15: =SUM(J13:J14) | M15: X
C16: % of Revenue | G16: =+G15/G11 | H16: =+H15/H11 | I16: =+I15/I11 | J16: =+J15/J11 | M16: X
M17: X
C18: Gross Profit | G18: =+G11-G15 | H18: =+H11-H15 | I18: =+I11-I15 | J18: =+J11-J15 | M18: X
C19: % Gross Margin | G19: =+G18/G11 | H19: =+H18/H11 | I19: =+I18/I11 | J19: =+J18/J11 | M19: X
M20: X
C21: General & Administrative | G21: =200.294+32.747 | H21: =287.834+28.284 | I21: =348.958+29.897 | J21: =373.218+30.346 | M21: X
C22: Sales & Marketing | G22: 0 | H22: 0 | I22: 0 | J22: 0 | M22: X
C23: Research & Development | G23: 0 | H23: 0 | I23: 0 | J23: 0 | M23: X
C24: Total Operating Expenses | G24: =SUM(G23,G22,G21) | H24: =SUM(H23,H22,H21) | I24: =SUM(I23,I22,I21) | J24: =SUM(J23,J22,J21) | M24: X
C25: % of Revenue | G25: =+G24/G$11 | H25: =+H24/H$11 | I25: =+I24/I$11 | J25: =+J24/J$11 | M25: X
M26: X
C27: EBITDA | G27: =+G18-G24 | H27: =+H18-H24 | I27: =+I18-I24 | J27: =+J18-J24 | M27: X
C28: % EBITDA Margin | G28: =+G27/G$11 | H28: =+H27/H$11 | I28: =+I27/I$11 | J28: =+J27/J$11 | M28: X
M29: X
C30: Depreciation | G30: 159.684 | H30: 190.256 | I30: 217.784 | J30: 238.466 | M30: X
C31: Amortization | G31: 0 | H31: 0 | I31: 0 | J31: 0 | M31: X
M32: X
C33: EBIT | G33: =+G27-SUM(G30:G31) | H33: =+H27-SUM(H30:H31) | I33: =+I27-SUM(I30:I31) | J33: =+J27-SUM(J30:J31) | M33: X
C34: % EBIT Margin | G34: =+G33/G$11 | H34: =+H33/H$11 | I34: =+I33/I$11 | J34: =+J33/J$11 | M34: X
M35: X
C36: Interest Expense | G36: 2.614 | H36: 3.127 | I36: 2.019 | J36: 1.866 | M36: X
M37: X
C38: Interest income, gross (= -(Interest income, net + interest paid)) | G38: =-(65.928+2.614) | H38: =-(145.673+3.127) | I38: =-(178.909+2.019) | J38: =-(181.923+1.866) | M38: X
C39: Other (income) expense, net | G39: -1.831 | H39: 3.095 | I39: -19.958 | J39: -0.464 | M39: X
C40: Net loss attributable to noncontrolling interest | G40: 0 | H40: -0.673 | I40: -4.086 | J40: -3.873 | M40: X
...

Sheet Financial Model
K1: =YEAR('Historical Financials'!J1)+1 | L1: =K1+1 | M1: =L1+1 | N1: =M1+1 | O1: =N1+1 | P1: =O1+1 | Q1: =P1+1 | R1: =Q1+1 | S1: =R1+1 | T1: =S1+1
C3: =Assumptions!G5
A4: X | C4: Income Statement | J4: FY26A / LTM
C5: =Assumptions!$G$9 | G5: ='Historical Financials'!G5 | H5: ='Historical Financials'!H5 | I5: ='Historical Financials'!I5 | J5: ='Historical Financials'!J5 | K5: ="FY"&K$1&"E" | L5: ="FY"&L$1&"E" | M5: ="FY"&M$1&"E" | N5: ="FY"&N$1&"E" | O5: ="FY"&O$1&"E" | P5: ="FY"&P$1&"E" | Q5: ="FY"&Q$1&"E" | R5: ="FY"&R$1&"E" | ... T5: ="FY"&T$1&"E"
C7: =+'Historical Financials'!C9 | G7: =+'Historical Financials'!G9/Conversion_Rate | H7: =+'Historical Financials'!H9/Conversion_Rate | I7: =+'Historical Financials'!I9/Conversion_Rate | J7: =+'Historical Financials'!J9/Conversion_Rate | K7: =+Drivers!K8 | L7: =+Drivers!L8 | M7: =+Drivers!M8 | N7: =+Drivers!N8 | O7: =+Drivers!O8 | P7: =+Drivers!P8 | Q7: =+Drivers!Q8 | R7: =+Drivers!R8 | ... T7: =+Drivers!T8
C8: =+'Historical Financials'!C10 | G8: =+'Historical Financials'!G10/Conversion_Rate | H8: =+'Historical Financials'!H10/Conversion_Rate | I8: =+'Historical Financials'!I10/Conversion_Rate | J8: =+'Historical Financials'!J10/Conversion_Rate | K8: =+Drivers!K13 | L8: =+Drivers!L13 | M8: =+Drivers!M13 | N8: =+Drivers!N13 | O8: =+Drivers!O13 | P8: =+Drivers!P13 | Q8: =+Drivers!Q13 | R8: =+Drivers!R13 | ... T8: =+Drivers!T13
C9: Revenue | G9: =SUM(G7:G8) | H9: =SUM(H7:H8) | I9: =SUM(I7:I8) | J9: =SUM(J7:J8) | K9: =SUM(K7:K8) | L9: =SUM(L7:L8) | M9: =SUM(M7:M8) | N9: =SUM(N7:N8) | ... T9: =SUM(T7:T8)
C10: Growth | G10: =G9/3500.921-1 | H10: =H9/G9-1 | I10: =I9/H9-1 | J10: =J9/I9-1 | K10: =K9/J9-1 | L10: =L9/K9-1 | M10: =M9/L9-1 | N10: =N9/M9-1 | O10: =O9/N9-1 | ... T10: =T9/S9-1
C12: ='Historical Financials'!C13 | G12: ='Historical Financials'!G13/Conversion_Rate | H12: ='Historical Financials'!H13/Conversion_Rate | I12: ='Historical Financials'!I13/Conversion_Rate | J12: ='Historical Financials'!J13/Conversion_Rate | K12: =+Drivers!K19 | L12: =+Drivers!L19 | M12: =+Drivers!M19 | N12: =+Drivers!N19 | O12: =+Drivers!O19 | P12: =+Drivers!P19 | Q12: =+Drivers!Q19 | R12: =+Drivers!R19 | ... T12: =+Drivers!T19
C13: ='Historical Financials'!C14 | G13: ='Historical Financials'!G14/Conversion_Rate | H13: ='Historical Financials'!H14/Conversion_Rate | I13: ='Historical Financials'!I14/Conversion_Rate | J13: ='Historical Financials'!J14/Conversion_Rate | K13: =+Drivers!K24 | L13: =+Drivers!L24 | M13: =+Drivers!M24 | N13: =+Drivers!N24 | O13: =+Drivers!O24 | P13: =+Drivers!P24 | Q13: =+Drivers!Q24 | R13: =+Drivers!R24 | ... T13: =+Drivers!T24
C14: Cost of Goods Sold | G14: =SUM(G12:G13) | H14: =SUM(H12:H13) | I14: =SUM(I12:I13) | J14: =SUM(J12:J13) | K14: =SUM(K12:K13) | L14: =SUM(L12:L13) | M14: =SUM(M12:M13) | N14: =SUM(N12:N13) | ... T14: =SUM(T12:T13)
C16: Gross Profit 1 | G16: =+G7-G12 | H16: =+H7-H12 | I16: =+I7-I12 | J16: =+J7-J12 | K16: =+K7-K12 | L16: =+L7-L12 | M16: =+M7-M12 | N16: =+N7-N12 | ... T16: =+T7-T12
C17: Gross Profit 2 | G17: =+G8-G13 | H17: =+H8-H13 | I17: =+I8-I13 | J17: =+J8-J13 | K17: =+K8-K13 | L17: =+L8-L13 | M17: =+M8-M13 | N17: =+N8-N13 | ... T17: =+T8-T13
C18: Gross Profit | G18: =G9-G14 | H18: =H9-H14 | I18: =I9-I14 | J18: =J9-J14 | K18: =K9-K14 | L18: =L9-L14 | M18: =M9-M14 | N18: =N9-N14 | ... T18: =T9-T14
C19: Gross Margin | G19: =G18/G$9 | H19: =H18/H$9 | I19: =I18/I$9 | J19: =J18/J$9 | K19: =K18/K$9 | L19: =L18/L$9 | M19: =M18/M$9 | N19: =N18/N$9 | ... T19: =T18/T$9
C21: ='Historical Financials'!C21 | G21: ='Historical Financials'!G21/Conversion_Rate | H21: ='Historical Financials'!H21/Conversion_Rate | I21: ='Historical Financials'!I21/Conversion_Rate | J21: ='Historical Financials'!J21/Conversion_Rate | K21: =+Drivers!K30 | L21: =+Drivers!L30 | M21: =+Drivers!M30 | N21: =+Drivers!N30 | O21: =+Drivers!O30 | P21: =+Drivers!P30 | Q21: =+Drivers!Q30 | R21: =+Drivers!R30 | ... T21: =+Drivers!T30
C22: ='Historical Financials'!C22 | G22: ='Historical Financials'!G22/Conversion_Rate | H22: ='Historical Financials'!H22/Conversion_Rate | I22: ='Historical Financials'!I22/Conversion_Rate | J22: ='Historical Financials'!J22/Conversion_Rate | K22: =+Drivers!K35 | L22: =+Drivers!L35 | M22: =+Drivers!M35 | N22: =+Drivers!N35 | O22: =+Drivers!O35 | P22: =+Drivers!P35 | Q22: =+Drivers!Q35 | R22: =+Drivers!R35 | ... T22: =+Drivers!T35
C23: ='Historical Financials'!C23 | G23: ='Historical Financials'!G23/Conversion_Rate | H23: ='Historical Financials'!H23/Conversion_Rate | I23: ='Historical Financials'!I23/Conversion_Rate | J23: ='Historical Financials'!J23/Conversion_Rate | K23: =+Drivers!K40 | L23: =+Drivers!L40 | M23: =+Drivers!M40 | N23: =+Drivers!N40 | O23: =+Drivers!O40 | P23: =+Drivers!P40 | Q23: =+Drivers!Q40 | R23: =+Drivers!R40 | ... T23: =+Drivers!T40
C24: Opex | G24: =SUM(G21:G23) | H24: =SUM(H21:H23) | I24: =SUM(I21:I23) | J24: =SUM(J21:J23) | K24: =SUM(K21:K23) | L24: =SUM(L21:L23) | M24: =SUM(M21:M23) | N24: =SUM(N21:N23) | ... T24: =SUM(T21:T23)
C25: % of Revenue | G25: =G24/G$9 | H25: =H24/H$9 | I25: =I24/I$9 | J25: =J24/J$9 | K25: =K24/K$9 | L25: =L24/L$9 | M25: =M24/M$9 | N25: =N24/N$9 | ... T25: =T24/T$9
C27: EBITDA | G27: =G18-G24 | H27: =H18-H24 | I27: =I18-I24 | J27: =J18-J24 | K27: =K18-K24 | L27: =L18-L24 | M27: =M18-M24 | N27: =N18-N24 | ... T27: =T18-T24
C28: EBITDA Margin | G28: =G27/G$9 | H28: =H27/H$9 | I28: =I27/I$9 | J28: =J27/J$9 | K28: =K27/K$9 | L28: =L27/L$9 | M28: =M27/M$9 | N28: =N27/N$9 | ... T28: =T27/T$9
C30: ='Historical Financials'!$C$30 | G30: ='Historical Financials'!G30/Conversion_Rate | H30: ='Historical Financials'!H30/Conversion_Rate | I30: ='Historical Financials'!I30/Conversion_Rate | J30: ='Historical Financials'!J30/Conversion_Rate | K30: =+Drivers!K46 | L30: =+Drivers!L46 | M30: =+Drivers!M46 | N30: =+Drivers!N46 | O30: =+Drivers!O46 | P30: =+Drivers!P46 | Q30: =+Drivers!Q46 | R30: =+Drivers!R46 | ... T30: =+Drivers!T46
C31: ='Historical Financials'!$C$31 | G31: ='Historical Financials'!G31/Conversion_Rate | H31: ='Historical Financials'!H31/Conversion_Rate | I31: ='Historical Financials'!I31/Conversion_Rate | J31: ='Historical Financials'!J31/Conversion_Rate | K31: =+Drivers!K51 | L31: =+Drivers!L51 | M31: =+Drivers!M51 | N31: =+Drivers!N51 | O31: =+Drivers!O51 | P31: =+Drivers!P51 | Q31: =+Drivers!Q51 | R31: =+Drivers!R51 | ... T31: =+Drivers!T51
C32: EBIT | G32: =+G27-SUM(G30:G31) | H32: =+H27-SUM(H30:H31) | I32: =+I27-SUM(I30:I31) | J32: =+J27-SUM(J30:J31) | K32: =+K27-SUM(K30:K31) | L32: =+L27-SUM(L30:L31) | M32: =+M27-SUM(M30:M31) | N32: =+N27-SUM(N30:N31) | ... T32: =+T27-SUM(T30:T31)
C34: ='Historical Financials'!$C$36 | G34: ='Historical Financials'!G36/Conversion_Rate | H34: ='Historical Financials'!H36/Conversion_Rate | I34: ='Historical Financials'!I36/Conversion_Rate | J34: ='Historical Financials'!J36/Conversion_Rate | K34: =SUM(Drivers!K57,Drivers!K62) | L34: =SUM(Drivers!L57,Drivers!L62) | M34: =SUM(Drivers!M57,Drivers!M62) | N34: =SUM(Drivers!N57,Drivers!N62) | O34: =SUM(Drivers!O57,Drivers!O62) | P34: =SUM(Drivers!P57,Drivers!P62) | Q34: =SUM(Drivers!Q57,Drivers!Q62) | R34: =SUM(Drivers!R57,Drivers!R62) | ... T34: =SUM(Drivers!T57,Drivers!T62)
C35: ='Historical Financials'!$C$41 | G35: ='Historical Financials'!G41/Conversion_Rate | H35: ='Historical Financials'!H41/Conversion_Rate | I35: ='Historical Financials'!I41/Conversion_Rate | J35: ='Historical Financials'!J41/Conversion_Rate | K35: =+Drivers!K67 | L35: =+Drivers!L67 | M35: =+Drivers!M67 | N35: =+Drivers!N67 | O35: =+Drivers!O67 | P35: =+Drivers!P67 | Q35: =+Drivers!Q67 | R35: =+Drivers!R67 | ... T35: =+Drivers!T67
C36: Earnings Before Taxes | G36: =+G32-SUM(G34:G35) | H36: =+H32-SUM(H34:H35) | I36: =+I32-SUM(I34:I35) | J36: =+J32-SUM(J34:J35) | K36: =+K32-SUM(K34:K35) | L36: =+L32-SUM(L34:L35) | M36: =+M32-SUM(M34:M35) | N36: =+N32-SUM(N34:N35) | ... T36: =+T32-SUM(T34:T35)
C38: ='Historical Financials'!$C$47 | G38: ='Historical Financials'!G47/Conversion_Rate | H38: ='Historical Financials'!H47/Conversion_Rate | I38: ='Historical Financials'!I47/Conversion_Rate | J38: ='Historical Financials'!J47/Conversion_Rate | K38: =+Drivers!K72 | L38: =+Drivers!L72 | M38: =+Drivers!M72 | N38: =+Drivers!N72 | O38: =+Drivers!O72 | P38: =+Drivers!P72 | Q38: =+Drivers!Q72 | R38: =+Drivers!R72 | ... T38: =+Drivers!T72
C39: Tax Rate | G39: =+G38/G36 | H39: =+H38/H36 | I39: =+I38/I36 | J39: =+J38/J36 | K39: =+K38/K36 | L39: =+L38/L36 | M39: =+M38/M36 | N39: =+N38/N36 | ... T39: =+T38/T36
C41: Net Income | G41: =G36-G38 | H41: =H36-H38 | I41: =I36-I38 | J41: =J36-J38 | K41: =K36-K38 | L41: =L36-L38 | M41: =M36-M38 | N41: =N36-N38 | ... T41: =T36-T38
C42: Profit Margin | G42: =G41/G$9 | H42: =H41/H$9 | I42: =I41/I$9 | J42: =J41/J$9 | K42: =K41/K$9 | L42: =L41/L$9 | M42: =M41/M$9 | N42: =N41/N$9 | ... T42: =T41/T$9
C46: =Assumptions!G$5
A47: X | C47: Balance Sheet | J47: FY26A / LTM
C48: =Assumptions!$G$9 | G48: ='Historical Financials'!G5 | H48: ='Historical Financials'!H5 | I48: ='Historical Financials'!I5 | J48: ='Historical Financials'!J5 | K48: ="FY"&K$1&"E" | L48: ="FY"&L$1&"E" | M48: ="FY"&M$1&"E" | N48: ="FY"&N$1&"E" | O48: ="FY"&O$1&"E" | P48: ="FY"&P$1&"E" | Q48: ="FY"&Q$1&"E" | R48: ="FY"&R$1&"E" | ... T48: ="FY"&T$1&"E"
C50: ='Historical Financials'!$C$59 | G50: =+G136 | H50: =+H136 | I50: =+I136 | J50: =+J136 | K50: =+K136 | L50: =+L136 | M50: =+M136 | N50: =+N136 | ... T50: =+T136
C51: ='Historical Financials'!$C$60 | G51: ='Historical Financials'!G60/Conversion_Rate | H51: ='Historical Financials'!H60/Conversion_Rate | I51: ='Historical Financials'!I60/Conversion_Rate | J51: ='Historical Financials'!J60/Conversion_Rate | K51: =+Drivers!K83 | L51: =+Drivers!L83 | M51: =+Drivers!M83 | N51: =+Drivers!N83 | O51: =+Drivers!O83 | P51: =+Drivers!P83 | Q51: =+Drivers!Q83 | R51: =+Drivers!R83 | ... T51: =+Drivers!T83
C52: ='Historical Financials'!$C$61 | G52: ='Historical Financials'!G61/Conversion_Rate | H52: ='Historical Financials'!H61/Conversion_Rate | I52: ='Historical Financials'!I61/Conversion_Rate | J52: ='Historical Financials'!J61/Conversion_Rate | K52: =+Drivers!K88 | L52: =+Drivers!L88 | M52: =+Drivers!M88 | N52: =+Drivers!N88 | O52: =+Drivers!O88 | P52: =+Drivers!P88 | Q52: =+Drivers!Q88 | R52: =+Drivers!R88 | ... T52: =+Drivers!T88
C53: ='Historical Financials'!$C$62 | G53: ='Historical Financials'!G62/Conversion_Rate | H53: ='Historical Financials'!H62/Conversion_Rate | I53: ='Historical Financials'!I62/Conversion_Rate | J53: ='Historical Financials'!J62/Conversion_Rate | K53: =Drivers!K93 | L53: =Drivers!L93 | M53: =Drivers!M93 | N53: =Drivers!N93 | O53: =Drivers!O93 | P53: =Drivers!P93 | Q53: =Drivers!Q93 | R53: =Drivers!R93 | ... T53: =Drivers!T93
C54: ='Historical Financials'!$C$63 | G54: ='Historical Financials'!G63/Conversion_Rate | H54: ='Historical Financials'!H63/Conversion_Rate | I54: ='Historical Financials'!I63/Conversion_Rate | J54: ='Historical Financials'!J63/Conversion_Rate | K54: =+Drivers!K98 | L54: =+Drivers!L98 | M54: =+Drivers!M98 | N54: =+Drivers!N98 | O54: =+Drivers!O98 | P54: =+Drivers!P98 | Q54: =+Drivers!Q98 | R54: =+Drivers!R98 | ... T54: =+Drivers!T98
...

Sheet Drivers
V3: Notes
C4: =Assumptions!G5
A5: X | C5: Income Statement Drivers | J5: FY26A / LTM
C6: =Assumptions!$G$9 | G6: ='Historical Financials'!G5 | H6: ='Historical Financials'!H5 | I6: ='Historical Financials'!I5 | J6: ='Historical Financials'!J5 | K6: ="FY"&'Financial Model'!K$1&"E" | L6: ="FY"&'Financial Model'!L$1&"E" | M6: ="FY"&'Financial Model'!M$1&"E" | N6: ="FY"&'Financial Model'!N$1&"E" | O6: ="FY"&'Financial Model'!O$1&"E" | P6: ="FY"&'Financial Model'!P$1&"E" | Q6: ="FY"&'Financial Model'!Q$1&"E" | R6: ="FY"&'Financial Model'!R$1&"E" | ... T6: ="FY"&'Financial Model'!T$1&"E"
C8: =+'Financial Model'!C7 | G8: =+'Financial Model'!G7 | H8: =+'Financial Model'!H7 | I8: =+'Financial Model'!I7 | J8: =+'Financial Model'!J7 | K8: =+K10*K11 | L8: =+L10*L11 | M8: =+M10*M11 | N8: =+N10*N11 | O8: =+O10*O11 | P8: =+P10*P11 | Q8: =+Q10*Q11 | R8: =+R10*R11 | ... T8: =+T10*T11
C10: Units sold (millions) - indexed to memo 4.0M FY26 anchor | G10: =H10/(1+H192) | H10: =I10/(1+I192) | I10: =J10/(1+J192) | J10: =Support!$D$68 | K10: =J10*(1+K192) | L10: =K10*(1+L192) | M10: =L10*(1+M192) | N10: =M10*(1+N192) | O10: =N10*(1+O192) | P10: =O10*(1+P192) | Q10: =P10*(1+Q192) | R10: =Q10*(1+R192) | ... T10: =S10*(1+T192) | V10: Units = prior x (1+total unit growth, row 192). Levels are an index anchored on the memo 4.0M FY26 base; only growth rates are company-disclosed.
C11: Service revenue per unit ($) | G11: =G8/G10 | H11: =H8/H10 | I11: =I8/I10 | J11: =J8/J10 | K11: =J11*(1+K203) | L11: =K11*(1+L203) | M11: =L11*(1+M203) | N11: =M11*(1+N203) | O11: =N11*(1+O203) | P11: =O11*(1+P203) | Q11: =P11*(1+Q203) | R11: =Q11*(1+R203) | ... T11: =S11*(1+T203) | V11: Service revenue per unit = prior x (1+RPU growth, row 203).
C13: =+'Financial Model'!C8 | G13: =+'Financial Model'!G8 | H13: =+'Financial Model'!H8 | I13: =+'Financial Model'!I8 | J13: =+'Financial Model'!J8 | K13: =+K15*K16 | L13: =+L15*L16 | M13: =+M15*M16 | N13: =+N15*N16 | O13: =+O15*O16 | P13: =+P15*P16 | Q13: =+Q15*Q16 | R13: =+R15*R16 | ... T13: =+T15*T16
C15: Prior-year vehicle sales ($) | G15: 647.881 | H15: =G13 | I15: =H13 | J15: =I13 | K15: =J13 | L15: =K13 | M15: =L13 | N15: =M13 | O15: =N13 | ... T15: =S13
C16: Growth factor (units x price, same as service revenue) | G16: =G13/G15 | H16: =H13/H15 | I16: =I13/I15 | J16: =J13/J15 | K16: =(1+K192)*(1+K203) | L16: =(1+L192)*(1+L203) | M16: =(1+M192)*(1+M203) | N16: =(1+N192)*(1+N203) | O16: =(1+O192)*(1+O203) | P16: =(1+P192)*(1+P203) | Q16: =(1+Q192)*(1+Q203) | R16: =(1+R192)*(1+R203) | ... T16: =(1+T192)*(1+T203)
C19: =+'Financial Model'!C12 | G19: =+'Financial Model'!G12 | H19: =+'Financial Model'!H12 | I19: =+'Financial Model'!I12 | J19: =+'Financial Model'!J12 | K19: =+K21*K22 | L19: =+L21*L22 | M19: =+M21*M22 | N19: =+N21*N22 | O19: =+O21*O22 | P19: =+P21*P22 | Q19: =+Q21*Q22 | R19: =+R21*R22 | ... T19: =+T21*T22
C21: =+C8 | G21: =+G8 | H21: =+H8 | I21: =+I8 | J21: =+J8 | K21: =+K8 | L21: =+L8 | M21: =+M8 | N21: =+N8 | ... T21: =+T8
C22: % of Revenue 1 | G22: =+G19/G21 | H22: =+H19/H21 | I22: =+I19/I21 | J22: =+J19/J21 | K22: =('Financial Model'!K9*(1-K204)-'Financial Model'!K13-'Financial Model'!K24-SUM('Financial Model'!K30:K31)-K206)/K21 | L22: =('Financial Model'!L9*(1-L204)-'Financial Model'!L13-'Financial Model'!L24-SUM('Financial Model'!L30:L31)-L206)/L21 | M22: =('Financial Model'!M9*(1-M204)-'Financial Model'!M13-'Financial Model'!M24-SUM('Financial Model'!M30:M31)-M206)/M21 | N22: =('Financial Model'!N9*(1-N204)-'Financial Model'!N13-'Financial Model'!N24-SUM('Financial Model'!N30:N31)-N206)/N21 | O22: =('Financial Model'!O9*(1-O204)-'Financial Model'!O13-'Financial Model'!O24-SUM('Financial Model'!O30:O31)-O206)/O21 | P22: =('Financial Model'!P9*(1-P204)-'Financial Model'!P13-'Financial Model'!P24-SUM('Financial Model'!P30:P31)-P206)/P21 | Q22: =('Financial Model'!Q9*(1-Q204)-'Financial Model'!Q13-'Financial Model'!Q24-SUM('Financial Model'!Q30:Q31)-Q206)/Q21 | R22: =('Financial Model'!R9*(1-R204)-'Financial Model'!R13-'Financial Model'!R24-SUM('Financial Model'!R30:R31)-R206)/R21 | ... T22: =('Financial Model'!T9*(1-T204)-'Financial Model'!T13-'Financial Model'!T24-SUM('Financial Model'!T30:T31)-T206)/T21 | V22: This row carries the margin drop: 44.2% to 46.9% of service revenue in FY27E. It is the residual that delivers row 204. Base case: facility cost +$122M (+7.0%) on 3% fewer cars; per car, cost +10.3% vs revenue +4.0% (Q4 FY26 US: +14.2%).
C24: =+'Financial Model'!C13 | G24: =+'Financial Model'!G13 | H24: =+'Financial Model'!H13 | I24: =+'Financial Model'!I13 | J24: =+'Financial Model'!J13 | K24: =+K26*K27 | L24: =+L26*L27 | M24: =+M26*M27 | N24: =+N26*N27 | O24: =+O26*O27 | P24: =+P26*P27 | Q24: =+Q26*Q27 | R24: =+R26*R27 | ... T24: =+T26*T27
C26: =+C13 | G26: =+G13 | H26: =+H13 | I26: =+I13 | J26: =+J13 | K26: =+K13 | L26: =+L13 | M26: =+M13 | N26: =+N13 | ... T26: =+T13
C27: % of Revenue 2 | G27: =+G24/G26 | H27: =+H24/H26 | I27: =+I24/I26 | J27: =+J24/J26 | K27: =$J$27 | L27: =$J$27 | M27: =$J$27 | N27: =$J$27 | O27: =$J$27 | P27: =$J$27 | Q27: =$J$27 | R27: =$J$27 | ... T27: =$J$27 | V27: Held at FY26 (88.5% of vehicle sales): not a source of the margin drop.
C30: =+'Financial Model'!C21 | G30: =+'Financial Model'!G21 | H30: =+'Financial Model'!H21 | I30: =+'Financial Model'!I21 | J30: =+'Financial Model'!J21 | K30: =+K32*K33 | L30: =+L32*L33 | M30: =+M32*M33 | N30: =+N32*N33 | O30: =+O32*O33 | P30: =+P32*P33 | Q30: =+Q32*Q33 | R30: =+R32*R33 | ... T30: =+T32*T33
C32: Total Revenue | G32: =+'Financial Model'!G$9 | H32: =+'Financial Model'!H$9 | I32: =+'Financial Model'!I$9 | J32: =+'Financial Model'!J$9 | K32: =+'Financial Model'!K$9 | L32: =+'Financial Model'!L$9 | M32: =+'Financial Model'!M$9 | N32: =+'Financial Model'!N$9 | ... T32: =+'Financial Model'!T$9
C33: % of Total Revenue | G33: =+G30/G32 | H33: =+H30/H32 | I33: =+I30/I32 | J33: =+J30/J32 | K33: =$J$33 | L33: =$J$33 | M33: =$J$33 | N33: =$J$33 | O33: =$J$33 | P33: =$J$33 | Q33: =$J$33 | R33: =$J$33 | ... T33: =$J$33 | V33: Held at FY26 (8.6% of revenue): not a source of the FY27E drop. G&A took 263bp of margin FY23A-FY26A (6.0% to 8.6%).
C35: =+'Financial Model'!C22 | G35: =+'Financial Model'!G22 | H35: =+'Financial Model'!H22 | I35: =+'Financial Model'!I22 | J35: =+'Financial Model'!J22 | K35: =+K37*K38 | L35: =+L37*L38 | M35: =+M37*M38 | N35: =+N37*N38 | O35: =+O37*O38 | P35: =+P37*P38 | Q35: =+Q37*Q38 | R35: =+R37*R38 | ... T35: =+T37*T38
C37: Total Revenue | G37: =+'Financial Model'!G$9 | H37: =+'Financial Model'!H$9 | I37: =+'Financial Model'!I$9 | J37: =+'Financial Model'!J$9 | K37: =+'Financial Model'!K$9 | L37: =+'Financial Model'!L$9 | M37: =+'Financial Model'!M$9 | N37: =+'Financial Model'!N$9 | ... T37: =+'Financial Model'!T$9
C38: % of Total Revenue | G38: =+G35/G37 | H38: =+H35/H37 | I38: =+I35/I37 | J38: =+J35/J37 | K38: 0 | L38: 0 | M38: 0 | N38: 0 | O38: 0 | P38: 0 | Q38: 0 | R38: 0 | S38: 0 | T38: 0
C40: =+'Financial Model'!C23 | G40: =+'Financial Model'!G23 | H40: =+'Financial Model'!H23 | I40: =+'Financial Model'!I23 | J40: =+'Financial Model'!J23 | K40: =+K42*K43 | L40: =+L42*L43 | M40: =+M42*M43 | N40: =+N42*N43 | O40: =+O42*O43 | P40: =+P42*P43 | Q40: =+Q42*Q43 | R40: =+R42*R43 | ... T40: =+T42*T43
C42: Total Revenue | G42: =+'Financial Model'!G$9 | H42: =+'Financial Model'!H$9 | I42: =+'Financial Model'!I$9 | J42: =+'Financial Model'!J$9 | K42: =+'Financial Model'!K$9 | L42: =+'Financial Model'!L$9 | M42: =+'Financial Model'!M$9 | N42: =+'Financial Model'!N$9 | ... T42: =+'Financial Model'!T$9
C43: % of Total Revenue | G43: =+G40/G42 | H43: =+H40/H42 | I43: =+I40/I42 | J43: =+J40/J42 | K43: 0 | L43: 0 | M43: 0 | N43: 0 | O43: 0 | P43: 0 | Q43: 0 | R43: 0 | S43: 0 | T43: 0
C46: Depreciation | G46: =+'Financial Model'!G30 | H46: =+'Financial Model'!H30 | I46: =+'Financial Model'!I30 | J46: =+'Financial Model'!J30 | K46: =+K48*K49 | L46: =+L48*L49 | M46: =+M48*M49 | N46: =+N48*N49 | O46: =+O48*O49 | P46: =+P48*P49 | Q46: =+Q48*Q49 | R46: =+R48*R49 | ... T46: =+T48*T49
C48: Total Revenue | G48: =+'Financial Model'!G$9 | H48: =+'Financial Model'!H$9 | I48: =+'Financial Model'!I$9 | J48: =+'Financial Model'!J$9 | K48: =+'Financial Model'!K$9 | L48: =+'Financial Model'!L$9 | M48: =+'Financial Model'!M$9 | N48: =+'Financial Model'!N$9 | ... T48: =+'Financial Model'!T$9
C49: % of Total Revenue | G49: =+G46/G48 | H49: =+H46/H48 | I49: =+I46/I48 | J49: =+J46/J48 | K49: =($J$46/'Financial Model'!$I$59)*'Financial Model'!J59/K48 | L49: =($J$46/'Financial Model'!$I$59)*'Financial Model'!K59/L48 | M49: =($J$46/'Financial Model'!$I$59)*'Financial Model'!L59/M48 | N49: =($J$46/'Financial Model'!$I$59)*'Financial Model'!M59/N48 | O49: =($J$46/'Financial Model'!$I$59)*'Financial Model'!N59/O48 | P49: =($J$46/'Financial Model'!$I$59)*'Financial Model'!O59/P48 | Q49: =($J$46/'Financial Model'!$I$59)*'Financial Model'!P59/Q48 | R49: =($J$46/'Financial Model'!$I$59)*'Financial Model'!Q59/R48 | ... T49: =($J$46/'Financial Model'!$I$59)*'Financial Model'!S59/T48 | V49: D&A at FY26 rate on opening net PP&E (yards do not shrink with units). Rises from 5.1% to 5.8% of revenue by FY30E, absorbed inside the flat operating margin.
C51: Amortization | G51: =+'Financial Model'!G31 | H51: =+'Financial Model'!H31 | I51: =+'Financial Model'!I31 | J51: =+'Financial Model'!J31 | K51: =+K53*K54 | L51: =+L53*L54 | M51: =+M53*M54 | N51: =+N53*N54 | O51: =+O53*O54 | P51: =+P53*P54 | Q51: =+Q53*Q54 | R51: =+R53*R54 | ... T51: =+T53*T54
C53: Total Revenue | G53: =+'Financial Model'!G$9 | H53: =+'Financial Model'!H$9 | I53: =+'Financial Model'!I$9 | J53: =+'Financial Model'!J$9 | K53: =+'Financial Model'!K$9 | L53: =+'Financial Model'!L$9 | M53: =+'Financial Model'!M$9 | N53: =+'Financial Model'!N$9 | ... T53: =+'Financial Model'!T$9
C54: % of Total Revenue | G54: =+G51/G53 | H54: =+H51/H53 | I54: =+I51/I53 | J54: =+J51/J53 | K54: 0 | L54: 0 | M54: 0 | N54: 0 | O54: 0 | P54: 0 | Q54: 0 | R54: 0 | S54: 0 | T54: 0
C57: Revolver Interest | K57: =+K59*K60 | L57: =+L59*L60 | M57: =+M59*M60 | N57: =+N59*N60 | O57: =+O59*O60 | P57: =+P59*P60 | Q57: =+Q59*Q60 | R57: =+R59*R60 | ... T57: =+T59*T60
C59: Average Outstanding Balance | K59: =AVERAGE(K135,J135) | L59: =AVERAGE(K135:L135) | M59: =AVERAGE(L135:M135) | N59: =AVERAGE(M135:N135) | O59: =AVERAGE(N135:O135) | P59: =AVERAGE(O135:P135) | Q59: =AVERAGE(P135:Q135) | R59: =AVERAGE(Q135:R135) | S59: =AVERAGE(R135:S135) | T59: =AVERAGE(S135:T135) | V59: - This is subject to changed based on debt balance below
C60: Interest Rate | K60: 0 | L60: 0 | M60: 0 | N60: 0 | O60: 0 | P60: 0 | Q60: 0 | R60: 0 | S60: 0 | T60: 0
C62: Term Loan Interest | K62: =+K64*K65 | L62: =+L64*L65 | M62: =+M64*M65 | N62: =+N64*N65 | O62: =+O64*O65 | P62: =+P64*P65 | Q62: =+Q64*Q65 | R62: =+R64*R65 | ... T62: =+T64*T65
C64: Average Outstanding Balance | K64: =AVERAGE(K140,J140) | L64: =AVERAGE(K140:L140) | M64: =AVERAGE(L140:M140) | N64: =AVERAGE(M140:N140) | O64: =AVERAGE(N140:O140) | P64: =AVERAGE(O140:P140) | Q64: =AVERAGE(P140:Q140) | R64: =AVERAGE(Q140:R140) | S64: =AVERAGE(R140:S140) | T64: =AVERAGE(S140:T140) | V64: - This is subject to changed based on debt balance below
C65: Interest Rate | K65: 0 | L65: 0 | M65: 0 | N65: 0 | O65: 0 | P65: 0 | Q65: 0 | R65: 0 | S65: 0 | T65: 0
C67: =+'Financial Model'!C35 | G67: =+'Financial Model'!G35 | H67: =+'Financial Model'!H35 | I67: =+'Financial Model'!I35 | J67: =+'Financial Model'!J35 | K67: =+K69*K70 | L67: =+L69*L70 | M67: =+M69*M70 | N67: =+N69*N70 | O67: =+O69*O70 | P67: =+P69*P70 | Q67: =+Q69*Q70 | R67: =+R69*R70 | ... T67: =+T69*T70
C69: Total Revenue | G69: =+'Financial Model'!G$9 | H69: =+'Financial Model'!H$9 | I69: =+'Financial Model'!I$9 | J69: =+'Financial Model'!J$9 | K69: =+'Financial Model'!K$9 | L69: =+'Financial Model'!L$9 | M69: =+'Financial Model'!M$9 | N69: =+'Financial Model'!N$9 | ... T69: =+'Financial Model'!T$9
C70: % of Total Revenue | G70: =+G67/G69 | H70: =+H67/H69 | I70: =+I67/I69 | J70: =+J67/J69 | K70: =-K207/K69 | L70: =-L207/L69 | M70: =-M207/M69 | N70: =-N207/N69 | O70: =-O207/O69 | P70: =-P207/P69 | Q70: =-Q207/Q69 | R70: =-R207/R69 | ... T70: =-T207/T69 | V70: Other income per row 207 (memo $110M FY27E; then FY26 yield x opening cash).
...

Sheet Multiples & Ratios
K1: =YEAR('Historical Financials'!J1)+1 | L1: =K1+1 | M1: =L1+1 | N1: =M1+1 | O1: =N1+1 | P1: =O1+1 | Q1: =P1+1 | R1: =Q1+1 | S1: =R1+1 | T1: =S1+1
C3: =Assumptions!G5
A4: X | C4: Multiples & Ratios | J4: FY26A / LTM
C5: =Assumptions!$G$9 | G5: ='Historical Financials'!G5 | H5: ='Historical Financials'!H5 | I5: ='Historical Financials'!I5 | J5: ='Historical Financials'!J5 | K5: ="FY"&K$1&"E" | L5: ="FY"&L$1&"E" | M5: ="FY"&M$1&"E" | N5: ="FY"&N$1&"E" | O5: ="FY"&O$1&"E" | P5: ="FY"&P$1&"E" | Q5: ="FY"&Q$1&"E" | R5: ="FY"&R$1&"E" | ... T5: ="FY"&T$1&"E"
C7: Valuation
C8: EV / Sales | G8: =G55/G66 | H8: =H55/H66 | I8: =I55/I66 | J8: =J55/J66 | K8: =K55/K66 | L8: =L55/L66 | M8: =M55/M66 | N8: =N55/N66 | ... T8: =T55/T66
C9: EV / EBITDA | G9: =G55/G68 | H9: =H55/H68 | I9: =I55/I68 | J9: =J55/J68 | K9: =K55/K68 | L9: =L55/L68 | M9: =M55/M68 | N9: =N55/N68 | ... T9: =T55/T68
C10: EV / FCFF | G10: =G55/G71 | H10: =H55/H71 | I10: =I55/I71 | J10: =J55/J71 | K10: =K55/K71 | L10: =L55/L71 | M10: =M55/M71 | N10: =N55/N71 | ... T10: =T55/T71
C11: P / E | G11: =G52/G70 | H11: =H52/H70 | I11: =I52/I70 | J11: =J52/J70 | K11: =K52/K70 | L11: =L52/L70 | M11: =M52/M70 | N11: =N52/N70 | ... T11: =T52/T70
C13: Profitability
C14: ='Financial Model'!C19 | G14: ='Financial Model'!G19 | H14: ='Financial Model'!H19 | I14: ='Financial Model'!I19 | J14: ='Financial Model'!J19 | K14: ='Financial Model'!K19 | L14: ='Financial Model'!L19 | M14: ='Financial Model'!M19 | N14: ='Financial Model'!N19 | ... T14: ='Financial Model'!T19
C15: ='Financial Model'!C28 | G15: ='Financial Model'!G28 | H15: ='Financial Model'!H28 | I15: ='Financial Model'!I28 | J15: ='Financial Model'!J28 | K15: ='Financial Model'!K28 | L15: ='Financial Model'!L28 | M15: ='Financial Model'!M28 | N15: ='Financial Model'!N28 | ... T15: ='Financial Model'!T28
C16: ='Financial Model'!C42 | G16: ='Financial Model'!G42 | H16: ='Financial Model'!H42 | I16: ='Financial Model'!I42 | J16: ='Financial Model'!J42 | K16: ='Financial Model'!K42 | L16: ='Financial Model'!L42 | M16: ='Financial Model'!M42 | N16: ='Financial Model'!N42 | ... T16: ='Financial Model'!T42
C17: FCF Margin | G17: =Summary!G25 | H17: =Summary!H25 | I17: =Summary!I25 | J17: =Summary!J25 | K17: =Summary!K25 | L17: =Summary!L25 | M17: =Summary!M25 | N17: =Summary!N25 | ... T17: =Summary!T25
C19: KPIs
C20: US insurance unit growth | G20: n/a | H20: =Drivers!H194 | I20: =Drivers!I194 | J20: =Drivers!J194 | K20: =Drivers!K194 | L20: =Drivers!L194 | M20: =Drivers!M194 | N20: =Drivers!N194 | O20: =Drivers!O194 | ... T20: =Drivers!T194
C21: Revenue per unit growth | G21: n/a | H21: =Drivers!H203 | I21: =Drivers!I203 | J21: =Drivers!J203 | K21: =Drivers!K203 | L21: =Drivers!L203 | M21: =Drivers!M203 | N21: =Drivers!N203 | O21: =Drivers!O203 | ... T21: =Drivers!T203
C22: Copart share of Copart + IAA units | G22: n/a | H22: n/a | I22: =Drivers!I218 | J22: =Drivers!J218 | K22: n/a | L22: n/a | M22: n/a | N22: n/a | O22: n/a | P22: n/a | Q22: n/a | R22: n/a | S22: n/a | T22: n/a
C24: Investor Returns
C25: ROA | G25: =G70/G62 | H25: =H70/H62 | I25: =I70/I62 | J25: =J70/J62 | K25: =K70/K62 | L25: =L70/L62 | M25: =M70/M62 | N25: =N70/N62 | ... T25: =T70/T62
C26: ROE | G26: =G70/G64 | H26: =H70/H64 | I26: =I70/I64 | J26: =J70/J64 | K26: =K70/K64 | L26: =L70/L64 | M26: =M70/M64 | N26: =N70/N64 | ... T26: =T70/T64
C27: ROIC | G27: =G72/SUM(G64,G53) | H27: =H72/SUM(H64,H53) | I27: =I72/SUM(I64,I53) | J27: =J72/SUM(J64,J53) | K27: =K72/SUM(K64,K53) | L27: =L72/SUM(L64,L53) | M27: =M72/SUM(M64,M53) | N27: =N72/SUM(N64,N53) | ... T27: =T72/SUM(T64,T53)
C28: EPS | G28: =G70/G57 | H28: =H70/H57 | I28: =I70/I57 | J28: =J70/J57 | K28: =K70/K57 | L28: =L70/L57 | M28: =M70/M57 | N28: =N70/N57 | ... T28: =T70/T57
C30: Asset Efficiency
C31: Asset Turnover | G31: =G66/G62 | H31: =H66/H62 | I31: =I66/I62 | J31: =J66/J62 | K31: =K66/K62 | L31: =L66/L62 | M31: =M66/M62 | N31: =N66/N62 | ... T31: =T66/T62
C32: Inventory Turnover | G32: =G67/G60 | H32: =H67/H60 | I32: =I67/I60 | J32: =J67/J60 | K32: =K67/K60 | L32: =L67/L60 | M32: =M67/M60 | N32: =N67/N60 | ... T32: =T67/T60
C33: Receivables Turnover | G33: =G66/G59 | H33: =H66/H59 | I33: =I66/I59 | J33: =J66/J59 | K33: =K66/K59 | L33: =L66/L59 | M33: =M66/M59 | N33: =N66/N59 | ... T33: =T66/T59
C34: =Drivers!C86 | G34: =Drivers!G86 | H34: =Drivers!H86 | I34: =Drivers!I86 | J34: =Drivers!J86 | K34: =Drivers!K86 | L34: =Drivers!L86 | M34: =Drivers!M86 | N34: =Drivers!N86 | ... T34: =Drivers!T86
C35: =Drivers!C112 | G35: =Drivers!G112 | H35: =Drivers!H112 | I35: =Drivers!I112 | J35: =Drivers!J112 | K35: =Drivers!K112 | L35: =Drivers!L112 | M35: =Drivers!M112 | N35: =Drivers!N112 | ... T35: =Drivers!T112
C37: Leverage
C38: Debt / Assets | G38: =G53/G62 | H38: =H53/H62 | I38: =I53/I62 | J38: =J53/J62 | K38: =K53/K62 | L38: =L53/L62 | M38: =M53/M62 | N38: =N53/N62 | ... T38: =T53/T62
C39: Debt / Equity | G39: =G53/G52 | H39: =H53/H52 | I39: =I53/I52 | J39: =J53/J52 | K39: =K53/K52 | L39: =L53/L52 | M39: =M53/M52 | N39: =N53/N52 | ... T39: =T53/T52
C40: Debt / EBITDA | G40: =G53/G68 | H40: =H53/H68 | I40: =I53/I68 | J40: =J53/J68 | K40: =K53/K68 | L40: =L53/L68 | M40: =M53/M68 | N40: =N53/N68 | ... T40: =T53/T68
C41: Interest Coverage | G41: =IFERROR(G69/G74,"n/m") | H41: =IFERROR(H69/H74,"n/m") | I41: =IFERROR(I69/I74,"n/m") | J41: =IFERROR(J69/J74,"n/m") | K41: =IFERROR(K69/K74,"n/m") | L41: =IFERROR(L69/L74,"n/m") | M41: =IFERROR(M69/M74,"n/m") | N41: =IFERROR(N69/N74,"n/m") | ... T41: =IFERROR(T69/T74,"n/m")
C42: Debt Service Coverage | G42: =IFERROR(G69/G76,"n/m") | H42: =IFERROR(H69/H76,"n/m") | I42: =IFERROR(I69/I76,"n/m") | J42: =IFERROR(J69/J76,"n/m") | K42: =IFERROR(K69/K76,"n/m") | L42: =IFERROR(L69/L76,"n/m") | M42: =IFERROR(M69/M76,"n/m") | N42: =IFERROR(N69/N76,"n/m") | ... T42: =IFERROR(T69/T76,"n/m")
C44: Liquidity
C45: Current Ratio | G45: =G61/G63 | H45: =H61/H63 | I45: =I61/I63 | J45: =J61/J63 | K45: =K61/K63 | L45: =L61/L63 | M45: =M61/M63 | N45: =N61/N63 | ... T45: =T61/T63
C46: Acid-Test Ratio | G46: =(G61-G60)/G63 | H46: =(H61-H60)/H63 | I46: =(I61-I60)/I63 | J46: =(J61-J60)/J63 | K46: =(K61-K60)/K63 | L46: =(L61-L60)/L63 | M46: =(M61-M60)/M63 | N46: =(N61-N60)/N63 | ... T46: =(T61-T60)/T63
C47: Cash Ratio | G47: =G54/G63 | H47: =H54/H63 | I47: =I54/I63 | J47: =J54/J63 | K47: =K54/K63 | L47: =L54/L63 | M47: =M54/M63 | N47: =N54/N63 | ... T47: =T54/T63
C50: Supporting Information
...

Sheet Valuation ->

Sheet DCF
C3: =Assumptions!$G$5
A4: X | C4: DCF Analysis | R4: X
C5: =Assumptions!$G$9 | G5: =Drivers!K6 | H5: =Drivers!L6 | I5: =Drivers!M6 | J5: =Drivers!N6 | K5: =Drivers!O6 | L5: =Drivers!P6 | M5: =Drivers!Q6 | N5: =Drivers!R6 | ... P5: =Drivers!T6 | R5: X
R6: X
C7: EBIT | G7: ='Financial Model'!K32 | H7: ='Financial Model'!L32 | I7: ='Financial Model'!M32 | J7: ='Financial Model'!N32 | K7: ='Financial Model'!O32 | L7: ='Financial Model'!P32 | M7: ='Financial Model'!Q32 | N7: ='Financial Model'!R32 | ... P7: ='Financial Model'!T32 | R7: X
C8: x (1 - Tax Rate) | G8: =1-'Financial Model'!K39 | H8: =1-'Financial Model'!L39 | I8: =1-'Financial Model'!M39 | J8: =1-'Financial Model'!N39 | K8: =1-'Financial Model'!O39 | L8: =1-'Financial Model'!P39 | M8: =1-'Financial Model'!Q39 | N8: =1-'Financial Model'!R39 | ... P8: =1-'Financial Model'!T39 | R8: X
C9: + Depreciation & Amortization | G9: =SUM('Financial Model'!K99:K100) | H9: =SUM('Financial Model'!L99:L100) | I9: =SUM('Financial Model'!M99:M100) | J9: =SUM('Financial Model'!N99:N100) | K9: =SUM('Financial Model'!O99:O100) | L9: =SUM('Financial Model'!P99:P100) | M9: =SUM('Financial Model'!Q99:Q100) | N9: =SUM('Financial Model'!R99:R100) | ... P9: =SUM('Financial Model'!T99:T100) | R9: X
C10: + Changes in Net Working Capital | G10: ='Financial Model'!K114 | H10: ='Financial Model'!L114 | I10: ='Financial Model'!M114 | J10: ='Financial Model'!N114 | K10: ='Financial Model'!O114 | L10: ='Financial Model'!P114 | M10: ='Financial Model'!Q114 | N10: ='Financial Model'!R114 | ... P10: ='Financial Model'!T114 | R10: X
C11: + Other Non-Cash | G11: ='Financial Model'!K102 | H11: ='Financial Model'!L102 | I11: ='Financial Model'!M102 | J11: ='Financial Model'!N102 | K11: ='Financial Model'!O102 | L11: ='Financial Model'!P102 | M11: ='Financial Model'!Q102 | N11: ='Financial Model'!R102 | ... P11: ='Financial Model'!T102 | R11: X
C12: - Capital Expenditures | G12: ='Financial Model'!K118 | H12: ='Financial Model'!L118 | I12: ='Financial Model'!M118 | J12: ='Financial Model'!N118 | K12: ='Financial Model'!O118 | L12: ='Financial Model'!P118 | M12: ='Financial Model'!Q118 | N12: ='Financial Model'!R118 | ... P12: ='Financial Model'!T118 | R12: X
C13: Unlevered Free Cash Flow (FCFF) | G13: =G7*G8+SUM(G9:G12) | H13: =H7*H8+SUM(H9:H12) | I13: =I7*I8+SUM(I9:I12) | J13: =J7*J8+SUM(J9:J12) | K13: =K7*K8+SUM(K9:K12) | L13: =L7*L8+SUM(L9:L12) | M13: =M7*M8+SUM(M9:M12) | N13: =N7*N8+SUM(N9:N12) | ... P13: =P7*P8+SUM(P9:P12) | R13: X
R14: X
C15: NPV of FCFF | P15: =NPV(P61,G13:P13) | R15: X
R16: X
C17: Final Year FCF | P17: =P13 | R17: X
C18: x 1 + Perpetual Growth Rate | P18: 1.02 | R18: g = 2.0%
C19: / (WACC - Perpetual Growth Rate) | P19: =+P61-(P18-1) | R19: X
C20: Terminal Value | P20: =+P17*P18/P19 | R20: X
R21: X
C22: NPV of Terminal Value | P22: =PV(P61,COUNTA(G13:P13),,-P20,0) | R22: X
R23: X
C24: Enterprise Value | P24: =SUM(P22,P15) | R24: Equity bridge, per-share value and implied exit EV/EBITDA: Support rows 88-97. Cross-check only.
R25: X
R26: X
R27: X
C28: =Assumptions!$G$5 | R28: X
A29: X | C29: Cost of Capital | R29: X
C30: =Assumptions!$G$9 | P30: ='Financial Model'!J5 | R30: X
R31: X
C32: Cost of Equity | R32: X
R33: X
C34: Expected Return (Rm) | P34: =P36+0.0423 | R34: ERP 4.23%: Damodaran implied ERP (Jan 2026 annual update; Sep-2026 monthly print not retrieved)
R35: X
C36: Risk-Free Rate (Rf) | P36: 0.0529 | R36: Rf: 10-yr Treasury CMT 5.29% on 9/30/2026 (FRED DGS10)
R37: X
C38: Risk Premium (Rm - Rf) | P38: =+P34-P36 | R38: X
C39: x Beta | P39: 1 | R39: Beta 1.0 per brief (2-yr weekly vs S&P 500 not re-estimated here - no price history loaded)
C40: + Risk-Free Rate (Rf) | P40: =+P36 | R40: X
C41: Cost of Equity (%) | P41: =+P38*P39+P40 | R41: X
R42: X
...

Sheet Comps
C3: =Assumptions!$G$5
C4: Relative Valuation as of September 30, 2026 (memo date)
C5: =Assumptions!$G$9
A7: X | C7: Public Comparables | D7: Industry | E7: Country | F7: Valuation | H7: Financials ($MM's) | K7: Growth / Profitability (%) | N7: Valuation Multiples (x)
F8: EV | G8: Equity Value | H8: Revenue | I8: EBITDA | J8: Net Income | K8: Y/Y Growth | L8: EBITDA Margin | M8: Profit Margin | N8: EV / Revenue | O8: EV / EBITDA | P8: P/E | Q8: Fwd P/E (memo) | R8: Source
C9: RB Global (RBA; owns IAA) | D9: Marketplaces / salvage auctions | E9: Canada/US | L9: =IFERROR(I9/$H9,"n/m") | M9: =IFERROR(J9/$H9,"n/m") | N9: =IFERROR($F9/H9,"n/m") | O9: =IFERROR($F9/I9,"n/m") | P9: =IFERROR($G9/J9,"n/m") | Q9: 16.8 | R9: Memo: 16.8x forward P/E (Yahoo consensus, 9/30/2026)
C10: OPENLANE (KAR) | D10: Dealer wholesale auctions | E10: US | L10: =IFERROR(I10/$H10,"n/m") | M10: =IFERROR(J10/$H10,"n/m") | N10: =IFERROR($F10/H10,"n/m") | O10: =IFERROR($F10/I10,"n/m") | P10: =IFERROR($G10/J10,"n/m") | R10: Not sourced as of 9/30/2026 - left blank
C11: LKQ (floor reference only; excluded from median) | D11: Salvage-parts buyer | E11: US | L11: =IFERROR(I11/$H11,"n/m") | M11: =IFERROR(J11/$H11,"n/m") | N11: =IFERROR($F11/H11,"n/m") | O11: =IFERROR($F11/I11,"n/m") | P11: =IFERROR($G11/J11,"n/m") | Q11: 7.4 | R11: Memo: 7.4x forward P/E (Yahoo consensus, 9/30/2026)
C12: Copart (subject; from model, FY26A) | D12: Salvage auctions | E12: US | F12: =Support!$D$9 | G12: =Support!$D$5 | H12: ='Financial Model'!J9 | I12: ='Financial Model'!J27 | J12: ='Financial Model'!J41 | K12: ='Financial Model'!J10 | L12: =IFERROR(I12/$H12,"n/m") | M12: =IFERROR(J12/$H12,"n/m") | N12: =IFERROR($F12/H12,"n/m") | O12: =IFERROR($F12/I12,"n/m") | P12: =IFERROR($G12/J12,"n/m") | Q12: =Support!$D$101 | R12: P/E on $27.36 / FY26 EPS (memo 17.6x); EV/EBITDA 11.0x vs memo 11.1x
L13: =IFERROR(I13/$H13,"n/m") | M13: =IFERROR(J13/$H13,"n/m") | N13: =IFERROR($F13/H13,"n/m") | O13: =IFERROR($F13/I13,"n/m") | P13: =IFERROR($G13/J13,"n/m")
L14: =IFERROR(I14/$H14,"n/m") | M14: =IFERROR(J14/$H14,"n/m") | N14: =IFERROR($F14/H14,"n/m") | O14: =IFERROR($F14/I14,"n/m") | P14: =IFERROR($G14/J14,"n/m")
L15: =IFERROR(I15/$H15,"n/m") | M15: =IFERROR(J15/$H15,"n/m") | N15: =IFERROR($F15/H15,"n/m") | O15: =IFERROR($F15/I15,"n/m") | P15: =IFERROR($G15/J15,"n/m")
L16: =IFERROR(I16/$H16,"n/m") | M16: =IFERROR(J16/$H16,"n/m") | N16: =IFERROR($F16/H16,"n/m") | O16: =IFERROR($F16/I16,"n/m") | P16: =IFERROR($G16/J16,"n/m")
L17: =IFERROR(I17/$H17,"n/m") | M17: =IFERROR(J17/$H17,"n/m") | N17: =IFERROR($F17/H17,"n/m") | O17: =IFERROR($F17/I17,"n/m") | P17: =IFERROR($G17/J17,"n/m")
C19: Minimum | F19: =IFERROR(MIN(F9:F17),"n/m") | G19: =IFERROR(MIN(G9:G17),"n/m") | H19: =IFERROR(MIN(H9:H17),"n/m") | I19: =IFERROR(MIN(I9:I17),"n/m") | J19: =IFERROR(MIN(J9:J17),"n/m") | K19: =IFERROR(MIN(K9:K17),"n/m") | L19: =IFERROR(MIN(L9:L17),"n/m") | M19: =IFERROR(MIN(M9:M17),"n/m") | ... P19: =IFERROR(MIN(P9:P17),"n/m")
C20: Median | F20: =IFERROR(MEDIAN(F9:F17),"n/m") | G20: =IFERROR(MEDIAN(G9:G17),"n/m") | H20: =IFERROR(MEDIAN(H9:H17),"n/m") | I20: =IFERROR(MEDIAN(I9:I17),"n/m") | J20: =IFERROR(MEDIAN(J9:J17),"n/m") | K20: =IFERROR(MEDIAN(K9:K17),"n/m") | L20: =IFERROR(MEDIAN(L9:L17),"n/m") | M20: =IFERROR(MEDIAN(M9:M17),"n/m") | ... P20: =IFERROR(MEDIAN(P9:P17),"n/m") | Q20: =MEDIAN(Q9:Q10) | R20: Median used as target reference = RBA (OPENLANE blank); LKQ and Copart excluded. Stats in F:P reflect Copart row only.
C21: Mean | F21: =IFERROR(AVERAGE(F9:F17),"n/m") | G21: =IFERROR(AVERAGE(G9:G17),"n/m") | H21: =IFERROR(AVERAGE(H9:H17),"n/m") | I21: =IFERROR(AVERAGE(I9:I17),"n/m") | J21: =IFERROR(AVERAGE(J9:J17),"n/m") | K21: =IFERROR(AVERAGE(K9:K17),"n/m") | L21: =IFERROR(AVERAGE(L9:L17),"n/m") | M21: =IFERROR(AVERAGE(M9:M17),"n/m") | ... P21: =IFERROR(AVERAGE(P9:P17),"n/m")
C22: Max | F22: =IFERROR(MAX(F12:F17),"n/m") | G22: =IFERROR(MAX(G12:G17),"n/m") | H22: =IFERROR(MAX(H12:H17),"n/m") | I22: =IFERROR(MAX(I12:I17),"n/m") | J22: =IFERROR(MAX(J12:J17),"n/m") | K22: =IFERROR(MAX(K12:K17),"n/m") | L22: =IFERROR(MAX(L12:L17),"n/m") | M22: =IFERROR(MAX(M12:M17),"n/m") | ... P22: =IFERROR(MAX(P12:P17),"n/m")
A26: X | C26: Precedent Transactions | D26: Acquirer | E26: Close Date | F26: Valuation | H26: Financials ($MM's) | K26: Growth / Profitability (%) | N26: Valuation Multiples (x)
F27: EV | G27: Equity Value | H27: Revenue | I27: EBITDA | J27: Net Income | K27: Y/Y Growth | L27: EBITDA Margin | M27: Profit Margin | N27: EV / Revenue | O27: EV / EBITDA | P27: P/E
C28: IAA, Inc. | D28: Ritchie Bros. (RB Global) | E28: Mar 2023 (announced 11/7/2022) | F28: 7300 | G28: n/m | I28: =F28/13.6 | J28: n/m | K28: n/m | L28: =IFERROR(I28/$H28,"n/m") | M28: =IFERROR(J28/$H28,"n/m") | N28: =IFERROR($F28/H28,"n/m") | O28: =IFERROR($F28/I28,"n/m") | P28: n/m | R28: RBA 8-K 11/7/2022: ~$7.3B incl. $1.0B net debt; 13.6x LTM Adj. EBITDA. Revenue not loaded. https://www.sec.gov/Archives/edgar/data/1046102/000110465922115108/tm2229848d1_ex99-1.htm
C29: ACV Auctions | D29: Copart | E29: Pending (by CY-end 2026) | G29: 1900 | J29: n/m | K29: n/m | L29: =IFERROR(I29/$H29,"n/m") | M29: =IFERROR(J29/$H29,"n/m") | N29: =IFERROR($F29/H29,"n/m") | O29: =IFERROR($F29/I29,"n/m") | P29: n/m | R29: 8-K 9/10/2026: $10.50/sh cash, ~$1.9B equity value. EV and profit measure not disclosed - multiples left blank.
G30: n/m | J30: n/m | K30: n/m | L30: =IFERROR(I30/$H30,"n/m") | M30: =IFERROR(J30/$H30,"n/m") | N30: =IFERROR($F30/H30,"n/m") | O30: =IFERROR($F30/I30,"n/m") | P30: n/m
G31: n/m | J31: n/m | K31: n/m | L31: =IFERROR(I31/$H31,"n/m") | M31: =IFERROR(J31/$H31,"n/m") | N31: =IFERROR($F31/H31,"n/m") | O31: =IFERROR($F31/I31,"n/m") | P31: n/m
G32: n/m | J32: n/m | K32: n/m | L32: =IFERROR(I32/$H32,"n/m") | M32: =IFERROR(J32/$H32,"n/m") | N32: =IFERROR($F32/H32,"n/m") | O32: =IFERROR($F32/I32,"n/m") | P32: n/m
G33: n/m | J33: n/m | K33: n/m | L33: =IFERROR(I33/$H33,"n/m") | M33: =IFERROR(J33/$H33,"n/m") | N33: =IFERROR($F33/H33,"n/m") | O33: =IFERROR($F33/I33,"n/m") | P33: n/m
G34: n/m | J34: n/m | K34: n/m | L34: =IFERROR(I34/$H34,"n/m") | M34: =IFERROR(J34/$H34,"n/m") | N34: =IFERROR($F34/H34,"n/m") | O34: =IFERROR($F34/I34,"n/m") | P34: n/m
